[2023-02-02T10:38:18.989+0000] {taskinstance.py:1165} INFO - Dependencies all met for <TaskInstance: spotify_dag_prac.s3_to_redshift scheduled__2023-01-31T17:00:00+00:00 [queued]>
[2023-02-02T10:38:18.995+0000] {taskinstance.py:1165} INFO - Dependencies all met for <TaskInstance: spotify_dag_prac.s3_to_redshift scheduled__2023-01-31T17:00:00+00:00 [queued]>
[2023-02-02T10:38:18.995+0000] {taskinstance.py:1362} INFO - 
--------------------------------------------------------------------------------
[2023-02-02T10:38:18.995+0000] {taskinstance.py:1363} INFO - Starting attempt 1 of 2
[2023-02-02T10:38:18.995+0000] {taskinstance.py:1364} INFO - 
--------------------------------------------------------------------------------
[2023-02-02T10:38:19.008+0000] {taskinstance.py:1383} INFO - Executing <Task(S3ToRedshiftOperator): s3_to_redshift> on 2023-01-31 17:00:00+00:00
[2023-02-02T10:38:19.010+0000] {standard_task_runner.py:55} INFO - Started process 1497 to run task
[2023-02-02T10:38:19.014+0000] {standard_task_runner.py:82} INFO - Running: ['airflow', 'tasks', 'run', 'spotify_dag_prac', 's3_to_redshift', 'scheduled__2023-01-31T17:00:00+00:00', '--job-id', '556', '--raw', '--subdir', 'DAGS_FOLDER/prac.py', '--cfg-path', '/tmp/tmpmvp68gnm']
[2023-02-02T10:38:19.015+0000] {standard_task_runner.py:83} INFO - Job 556: Subtask s3_to_redshift
[2023-02-02T10:38:19.051+0000] {task_command.py:376} INFO - Running <TaskInstance: spotify_dag_prac.s3_to_redshift scheduled__2023-01-31T17:00:00+00:00 [running]> on host ip-172-31-26-59.ap-northeast-2.compute.internal
[2023-02-02T10:38:19.099+0000] {taskinstance.py:1590} INFO - Exporting the following env vars:
AIRFLOW_CTX_DAG_EMAIL=nywkim@example.com
AIRFLOW_CTX_DAG_OWNER=airflow
AIRFLOW_CTX_DAG_ID=spotify_dag_prac
AIRFLOW_CTX_TASK_ID=s3_to_redshift
AIRFLOW_CTX_EXECUTION_DATE=2023-01-31T17:00:00+00:00
AIRFLOW_CTX_TRY_NUMBER=1
AIRFLOW_CTX_DAG_RUN_ID=scheduled__2023-01-31T17:00:00+00:00
[2023-02-02T10:38:19.103+0000] {base.py:71} INFO - Using connection ID 'aws_default' for task execution.
[2023-02-02T10:38:19.106+0000] {base.py:71} INFO - Using connection ID 'aws_default' for task execution.
[2023-02-02T10:38:19.106+0000] {connection_wrapper.py:334} INFO - AWS Connection (conn_id='aws_default', conn_type='aws') credentials retrieved from login and password.
[2023-02-02T10:38:19.116+0000] {s3_to_redshift.py:164} INFO - Executing COPY command...
[2023-02-02T10:38:19.118+0000] {base.py:71} INFO - Using connection ID 'redshift_default' for task execution.
[2023-02-02T10:38:19.134+0000] {credentials.py:1251} INFO - Found credentials in shared credentials file: ~/.aws/credentials
[2023-02-02T10:38:19.409+0000] {iam_helper.py:359} ERROR - ClientError: An error occurred (UnsupportedOperation) when calling the GetClusterCredentials operation: You can't get credentials for a paused cluster
[2023-02-02T10:38:19.409+0000] {taskinstance.py:1851} ERROR - Task failed with exception
Traceback (most recent call last):
  File "/usr/local/lib/python3.10/dist-packages/airflow/providers/amazon/aws/transfers/s3_to_redshift.py", line 165, in execute
    redshift_hook.run(sql, autocommit=self.autocommit)
  File "/usr/local/lib/python3.10/dist-packages/airflow/providers/common/sql/hooks/sql.py", line 342, in run
    with closing(self.get_conn()) as conn:
  File "/usr/local/lib/python3.10/dist-packages/airflow/providers/amazon/aws/hooks/redshift_sql.py", line 129, in get_conn
    return redshift_connector.connect(**conn_kwargs)
  File "/usr/local/lib/python3.10/dist-packages/redshift_connector/__init__.py", line 332, in connect
    IamHelper.set_iam_properties(info)
  File "/usr/local/lib/python3.10/dist-packages/redshift_connector/iam_helper.py", line 116, in set_iam_properties
    IamHelper.set_iam_credentials(info)
  File "/usr/local/lib/python3.10/dist-packages/redshift_connector/iam_helper.py", line 176, in set_iam_credentials
    IamHelper.set_cluster_credentials(provider, info)
  File "/usr/local/lib/python3.10/dist-packages/redshift_connector/iam_helper.py", line 360, in set_cluster_credentials
    raise e
  File "/usr/local/lib/python3.10/dist-packages/redshift_connector/iam_helper.py", line 335, in set_cluster_credentials
    client.get_cluster_credentials(
  File "/usr/local/lib/python3.10/dist-packages/botocore/client.py", line 530, in _api_call
    return self._make_api_call(operation_name, kwargs)
  File "/usr/local/lib/python3.10/dist-packages/botocore/client.py", line 960, in _make_api_call
    raise error_class(parsed_response, operation_name)
botocore.errorfactory.UnsupportedOperationFault: An error occurred (UnsupportedOperation) when calling the GetClusterCredentials operation: You can't get credentials for a paused cluster
[2023-02-02T10:38:19.419+0000] {taskinstance.py:1401} INFO - Marking task as UP_FOR_RETRY. dag_id=spotify_dag_prac, task_id=s3_to_redshift, execution_date=20230131T170000, start_date=20230202T103818, end_date=20230202T103819
[2023-02-02T10:38:19.432+0000] {standard_task_runner.py:100} ERROR - Failed to execute job 556 for task s3_to_redshift (An error occurred (UnsupportedOperation) when calling the GetClusterCredentials operation: You can't get credentials for a paused cluster; 1497)
[2023-02-02T10:38:19.466+0000] {local_task_job.py:164} INFO - Task exited with return code 1
[2023-02-02T10:38:19.477+0000] {local_task_job.py:273} INFO - 0 downstream tasks scheduled from follow-on schedule check
