[2023-01-25T08:58:48.173+0000] {taskinstance.py:1165} INFO - Dependencies all met for <TaskInstance: practice.glue_job manual__2023-01-25T08:58:45.988349+00:00 [queued]>
[2023-01-25T08:58:48.178+0000] {taskinstance.py:1165} INFO - Dependencies all met for <TaskInstance: practice.glue_job manual__2023-01-25T08:58:45.988349+00:00 [queued]>
[2023-01-25T08:58:48.178+0000] {taskinstance.py:1362} INFO - 
--------------------------------------------------------------------------------
[2023-01-25T08:58:48.178+0000] {taskinstance.py:1363} INFO - Starting attempt 1 of 2
[2023-01-25T08:58:48.178+0000] {taskinstance.py:1364} INFO - 
--------------------------------------------------------------------------------
[2023-01-25T08:58:48.189+0000] {taskinstance.py:1383} INFO - Executing <Task(PythonOperator): glue_job> on 2023-01-25 08:58:45.988349+00:00
[2023-01-25T08:58:48.191+0000] {standard_task_runner.py:55} INFO - Started process 17960 to run task
[2023-01-25T08:58:48.195+0000] {standard_task_runner.py:82} INFO - Running: ['airflow', 'tasks', 'run', 'practice', 'glue_job', 'manual__2023-01-25T08:58:45.988349+00:00', '--job-id', '344', '--raw', '--subdir', 'DAGS_FOLDER/practice.py', '--cfg-path', '/tmp/tmpcz8_9ia3']
[2023-01-25T08:58:48.196+0000] {standard_task_runner.py:83} INFO - Job 344: Subtask glue_job
[2023-01-25T08:58:48.231+0000] {task_command.py:376} INFO - Running <TaskInstance: practice.glue_job manual__2023-01-25T08:58:45.988349+00:00 [running]> on host ip-172-31-26-59.ap-northeast-2.compute.internal
[2023-01-25T08:58:48.278+0000] {taskinstance.py:1590} INFO - Exporting the following env vars:
AIRFLOW_CTX_DAG_EMAIL=nywkim@example.com
AIRFLOW_CTX_DAG_OWNER=airflow
AIRFLOW_CTX_DAG_ID=practice
AIRFLOW_CTX_TASK_ID=glue_job
AIRFLOW_CTX_EXECUTION_DATE=2023-01-25T08:58:45.988349+00:00
AIRFLOW_CTX_TRY_NUMBER=1
AIRFLOW_CTX_DAG_RUN_ID=manual__2023-01-25T08:58:45.988349+00:00
[2023-01-25T08:58:48.298+0000] {credentials.py:1048} INFO - Found credentials from IAM Role: EC2_S3_Af
[2023-01-25T08:58:48.344+0000] {taskinstance.py:1851} ERROR - Task failed with exception
Traceback (most recent call last):
  File "/home/ubuntu/.local/lib/python3.10/site-packages/airflow/operators/python.py", line 175, in execute
    return_value = self.execute_callable()
  File "/home/ubuntu/.local/lib/python3.10/site-packages/airflow/operators/python.py", line 193, in execute_callable
    return self.python_callable(*self.op_args, **self.op_kwargs)
  File "/home/ubuntu/airflow/spotify_dag/practice.py", line 28, in GlueJobRun
    client = boto3.client('glue')
  File "/usr/local/lib/python3.10/dist-packages/boto3/__init__.py", line 92, in client
    return _get_default_session().client(*args, **kwargs)
  File "/usr/local/lib/python3.10/dist-packages/boto3/session.py", line 299, in client
    return self._session.create_client(
  File "/usr/local/lib/python3.10/dist-packages/botocore/session.py", line 976, in create_client
    client = client_creator.create_client(
  File "/usr/local/lib/python3.10/dist-packages/botocore/client.py", line 155, in create_client
    client_args = self._get_client_args(
  File "/usr/local/lib/python3.10/dist-packages/botocore/client.py", line 485, in _get_client_args
    return args_creator.get_client_args(
  File "/usr/local/lib/python3.10/dist-packages/botocore/args.py", line 92, in get_client_args
    final_args = self.compute_client_args(
  File "/usr/local/lib/python3.10/dist-packages/botocore/args.py", line 205, in compute_client_args
    endpoint_config = self._compute_endpoint_config(
  File "/usr/local/lib/python3.10/dist-packages/botocore/args.py", line 313, in _compute_endpoint_config
    return self._resolve_endpoint(**resolve_endpoint_kwargs)
  File "/usr/local/lib/python3.10/dist-packages/botocore/args.py", line 418, in _resolve_endpoint
    return endpoint_bridge.resolve(
  File "/usr/local/lib/python3.10/dist-packages/botocore/client.py", line 590, in resolve
    resolved = self.endpoint_resolver.construct_endpoint(
  File "/usr/local/lib/python3.10/dist-packages/botocore/regions.py", line 229, in construct_endpoint
    result = self._endpoint_for_partition(
  File "/usr/local/lib/python3.10/dist-packages/botocore/regions.py", line 277, in _endpoint_for_partition
    raise NoRegionError()
botocore.exceptions.NoRegionError: You must specify a region.
[2023-01-25T08:58:48.351+0000] {taskinstance.py:1401} INFO - Marking task as UP_FOR_RETRY. dag_id=practice, task_id=glue_job, execution_date=20230125T085845, start_date=20230125T085848, end_date=20230125T085848
[2023-01-25T08:58:48.361+0000] {standard_task_runner.py:100} ERROR - Failed to execute job 344 for task glue_job (You must specify a region.; 17960)
[2023-01-25T08:58:48.369+0000] {local_task_job.py:164} INFO - Task exited with return code 1
[2023-01-25T08:58:48.379+0000] {local_task_job.py:273} INFO - 0 downstream tasks scheduled from follow-on schedule check
