[2023-01-31T09:24:56.348+0000] {taskinstance.py:1165} INFO - Dependencies all met for <TaskInstance: spotify_dag_prac.s3_to_redshift manual__2023-01-31T09:24:54.622082+00:00 [queued]>
[2023-01-31T09:24:56.354+0000] {taskinstance.py:1165} INFO - Dependencies all met for <TaskInstance: spotify_dag_prac.s3_to_redshift manual__2023-01-31T09:24:54.622082+00:00 [queued]>
[2023-01-31T09:24:56.354+0000] {taskinstance.py:1362} INFO - 
--------------------------------------------------------------------------------
[2023-01-31T09:24:56.354+0000] {taskinstance.py:1363} INFO - Starting attempt 1 of 2
[2023-01-31T09:24:56.354+0000] {taskinstance.py:1364} INFO - 
--------------------------------------------------------------------------------
[2023-01-31T09:24:56.370+0000] {taskinstance.py:1383} INFO - Executing <Task(S3ToRedshiftOperator): s3_to_redshift> on 2023-01-31 09:24:54.622082+00:00
[2023-01-31T09:24:56.373+0000] {standard_task_runner.py:55} INFO - Started process 5405 to run task
[2023-01-31T09:24:56.376+0000] {standard_task_runner.py:82} INFO - Running: ['airflow', 'tasks', 'run', 'spotify_dag_prac', 's3_to_redshift', 'manual__2023-01-31T09:24:54.622082+00:00', '--job-id', '499', '--raw', '--subdir', 'DAGS_FOLDER/prac.py', '--cfg-path', '/tmp/tmp7fdgeg19']
[2023-01-31T09:24:56.377+0000] {standard_task_runner.py:83} INFO - Job 499: Subtask s3_to_redshift
[2023-01-31T09:24:56.413+0000] {task_command.py:376} INFO - Running <TaskInstance: spotify_dag_prac.s3_to_redshift manual__2023-01-31T09:24:54.622082+00:00 [running]> on host ip-172-31-26-59.ap-northeast-2.compute.internal
[2023-01-31T09:24:56.460+0000] {taskinstance.py:1590} INFO - Exporting the following env vars:
AIRFLOW_CTX_DAG_EMAIL=nywkim@example.com
AIRFLOW_CTX_DAG_OWNER=airflow
AIRFLOW_CTX_DAG_ID=spotify_dag_prac
AIRFLOW_CTX_TASK_ID=s3_to_redshift
AIRFLOW_CTX_EXECUTION_DATE=2023-01-31T09:24:54.622082+00:00
AIRFLOW_CTX_TRY_NUMBER=1
AIRFLOW_CTX_DAG_RUN_ID=manual__2023-01-31T09:24:54.622082+00:00
[2023-01-31T09:24:56.464+0000] {base.py:71} INFO - Using connection ID 'aws_default' for task execution.
[2023-01-31T09:24:56.466+0000] {base.py:71} INFO - Using connection ID 'aws_default' for task execution.
[2023-01-31T09:24:56.466+0000] {connection_wrapper.py:334} INFO - AWS Connection (conn_id='aws_default', conn_type='aws') credentials retrieved from login and password.
[2023-01-31T09:24:56.475+0000] {s3_to_redshift.py:164} INFO - Executing COPY command...
[2023-01-31T09:24:56.477+0000] {base.py:71} INFO - Using connection ID 'redshift_default' for task execution.
[2023-01-31T09:24:56.487+0000] {aws_credentials_provider.py:60} ERROR - Refreshing IdP credentials failed: The config profile (default) could not be found
[2023-01-31T09:24:56.488+0000] {iam_helper.py:362} ERROR - other Exception: The config profile (default) could not be found
[2023-01-31T09:24:56.488+0000] {taskinstance.py:1851} ERROR - Task failed with exception
Traceback (most recent call last):
  File "/usr/local/lib/python3.10/dist-packages/redshift_connector/auth/aws_credentials_provider.py", line 58, in get_credentials
    self.refresh()
  File "/usr/local/lib/python3.10/dist-packages/redshift_connector/auth/aws_credentials_provider.py", line 100, in refresh
    session: boto3.Session = boto3.Session(**args)
  File "/usr/local/lib/python3.10/dist-packages/boto3/session.py", line 90, in __init__
    self._setup_loader()
  File "/usr/local/lib/python3.10/dist-packages/boto3/session.py", line 131, in _setup_loader
    self._loader = self._session.get_component('data_loader')
  File "/usr/local/lib/python3.10/dist-packages/botocore/session.py", line 796, in get_component
    return self._components.get_component(name)
  File "/usr/local/lib/python3.10/dist-packages/botocore/session.py", line 1108, in get_component
    self._components[name] = factory()
  File "/usr/local/lib/python3.10/dist-packages/botocore/session.py", line 193, in <lambda>
    lambda: create_loader(self.get_config_variable('data_path')),
  File "/usr/local/lib/python3.10/dist-packages/botocore/session.py", line 317, in get_config_variable
    return self.get_component('config_store').get_config_variable(
  File "/usr/local/lib/python3.10/dist-packages/botocore/configprovider.py", line 426, in get_config_variable
    return provider.provide()
  File "/usr/local/lib/python3.10/dist-packages/botocore/configprovider.py", line 628, in provide
    value = provider.provide()
  File "/usr/local/lib/python3.10/dist-packages/botocore/configprovider.py", line 718, in provide
    scoped_config = self._session.get_scoped_config()
  File "/usr/local/lib/python3.10/dist-packages/botocore/session.py", line 416, in get_scoped_config
    raise ProfileNotFound(profile=profile_name)
botocore.exceptions.ProfileNotFound: The config profile (default) could not be found

During handling of the above exception, another exception occurred:

Traceback (most recent call last):
  File "/usr/local/lib/python3.10/dist-packages/airflow/providers/amazon/aws/transfers/s3_to_redshift.py", line 165, in execute
    redshift_hook.run(sql, autocommit=self.autocommit)
  File "/usr/local/lib/python3.10/dist-packages/airflow/providers/common/sql/hooks/sql.py", line 342, in run
    with closing(self.get_conn()) as conn:
  File "/usr/local/lib/python3.10/dist-packages/airflow/providers/amazon/aws/hooks/redshift_sql.py", line 129, in get_conn
    return redshift_connector.connect(**conn_kwargs)
  File "/usr/local/lib/python3.10/dist-packages/redshift_connector/__init__.py", line 332, in connect
    IamHelper.set_iam_properties(info)
  File "/usr/local/lib/python3.10/dist-packages/redshift_connector/iam_helper.py", line 116, in set_iam_properties
    IamHelper.set_iam_credentials(info)
  File "/usr/local/lib/python3.10/dist-packages/redshift_connector/iam_helper.py", line 176, in set_iam_credentials
    IamHelper.set_cluster_credentials(provider, info)
  File "/usr/local/lib/python3.10/dist-packages/redshift_connector/iam_helper.py", line 363, in set_cluster_credentials
    raise e
  File "/usr/local/lib/python3.10/dist-packages/redshift_connector/iam_helper.py", line 253, in set_cluster_credentials
    ] = cred_provider.get_credentials()  # type: ignore
  File "/usr/local/lib/python3.10/dist-packages/redshift_connector/auth/aws_credentials_provider.py", line 61, in get_credentials
    raise InterfaceError(e)
redshift_connector.error.InterfaceError: The config profile (default) could not be found
[2023-01-31T09:24:56.492+0000] {taskinstance.py:1401} INFO - Marking task as UP_FOR_RETRY. dag_id=spotify_dag_prac, task_id=s3_to_redshift, execution_date=20230131T092454, start_date=20230131T092456, end_date=20230131T092456
[2023-01-31T09:24:56.503+0000] {standard_task_runner.py:100} ERROR - Failed to execute job 499 for task s3_to_redshift (The config profile (default) could not be found; 5405)
[2023-01-31T09:24:56.508+0000] {local_task_job.py:164} INFO - Task exited with return code 1
[2023-01-31T09:24:56.518+0000] {local_task_job.py:273} INFO - 0 downstream tasks scheduled from follow-on schedule check
